<sdf version='1.7'>
  <model name='bigbot'>
    <link name='base_link'>
      <inertial>
        <pose>-0.241138 0 0.180902 0 -0 0</pose>
        <mass>13</mass>
        <inertia>
          <ixx>0.505675</ixx>
          <ixy>-2.06795e-25</ixy>
          <ixz>-0.0316503</ixz>
          <iyy>0.449154</iyy>
          <iyz>-4.59177e-41</iyz>
          <izz>0.924761</izz>
        </inertia>
      </inertial>
      <collision name='base_link_fixed_joint_lump__chassis_link_collision'>
        <pose>-0.22 0 0.1905 0 -0 0</pose>
        <geometry>
          <box>
            <size>0.7787 0.68185 0.0913</size>
          </box>
        </geometry>
        <surface>
          <contact>
            <ode/>
          </contact>
          <friction>
            <ode/>
          </friction>
        </surface>
      </collision>
      <collision name='base_link_fixed_joint_lump__caster_link_collision_1'>
        <pose>-0.4948 0 0.065725 1.5708 -0 0</pose>
        <geometry>
          <sphere>
            <radius>0.0635</radius>
          </sphere>
        </geometry>
        <surface>
          <contact>
            <ode/>
          </contact>
          <friction>
            <ode/>
          </friction>
        </surface>
      </collision>
      <collision name='base_link_fixed_joint_lump__laser_point_collision_2'>
        <pose>0.12144 0 0.13335 0 -0 0</pose>
        <geometry>
          <cylinder>
            <length>0.0001</length>
            <radius>0.0001</radius>
          </cylinder>
        </geometry>
      </collision>
      <collision name='base_link_fixed_joint_lump__laser_frame_collision_3'>
        <pose>0.12144 0 0.13335 3.14 -0 -1.57</pose>
        <geometry>
          <cylinder>
            <length>0.0508</length>
            <radius>0.0635</radius>
          </cylinder>
        </geometry>
      </collision>
      <visual name='base_link_visual'>
        <pose>0 0 0 0 -0 0</pose>
        <geometry>
          <box>
            <size>0.001 0.001 0.001</size>
          </box>
        </geometry>
        <material>
          <script>
            <name>Gazebo/Red</name>
            <uri>file://media/materials/scripts/gazebo.material</uri>
          </script>
        </material>
      </visual>
      <visual name='base_link_fixed_joint_lump__chassis_link_visual_1'>
        <pose>-0.22 0 0.19685 0 -0 0</pose>
        <geometry>
          <box>
            <size>0.7001 0.60325 0.0127</size>
          </box>
        </geometry>
        <material>
          <script>
            <name>Gazebo/White</name>
            <uri>file://media/materials/scripts/gazebo.material</uri>
          </script>
        </material>
      </visual>
      <visual name='base_link_fixed_joint_lump__caster_link_visual_2'>
        <pose>-0.4948 0 0.065725 1.5708 -0 0</pose>
        <geometry>
          <sphere>
            <radius>0.0635</radius>
          </sphere>
        </geometry>
        <material>
          <script>
            <name>Gazebo/Blue</name>
            <uri>file://media/materials/scripts/gazebo.material</uri>
          </script>
        </material>
      </visual>
      <visual name='base_link_fixed_joint_lump__laser_point_visual_3'>
        <pose>0.12144 0 0.13335 0 -0 0</pose>
        <geometry>
          <cylinder>
            <length>0.0001</length>
            <radius>0.0001</radius>
          </cylinder>
        </geometry>
      </visual>
      <visual name='base_link_fixed_joint_lump__laser_frame_visual_4'>
        <pose>0.12144 0 0.13335 3.14 -0 -1.57</pose>
        <geometry>
          <cylinder>
            <length>0.0508</length>
            <radius>0.0635</radius>
          </cylinder>
        </geometry>
      </visual>
      <gravity>1</gravity>
    </link>
    <joint name='base_to_left_wheel' type='revolute'>
      <pose relative_to='base_link'>0 0.27305 0.085725 1.5707 -0 0</pose>
      <parent>base_link</parent>
      <child>left_wheel</child>
      <axis>
        <xyz>0 0 1</xyz>
        <limit>
          <lower>-1e+16</lower>
          <upper>1e+16</upper>
        </limit>
        <dynamics>
          <spring_reference>0</spring_reference>
          <spring_stiffness>0</spring_stiffness>
        </dynamics>
      </axis>
    </joint>
    <link name='left_wheel'>
      <pose relative_to='base_to_left_wheel'>0 0 0 0 -0 0</pose>
      <inertial>
        <pose>0 0 0 0 -0 0</pose>
        <mass>1</mass>
        <inertia>
          <ixx>0.00222551</ixx>
          <ixy>0</ixy>
          <ixz>0</ixz>
          <iyy>0.00222551</iyy>
          <iyz>0</iyz>
          <izz>0.00367439</izz>
        </inertia>
      </inertial>
      <collision name='left_wheel_collision'>
        <pose>0 0 0 0 -0 0</pose>
        <geometry>
          <cylinder>
            <length>0.0682625</length>
            <radius>0.085725</radius>
          </cylinder>
        </geometry>
        <surface>
          <contact>
            <ode/>
          </contact>
          <friction>
            <ode/>
          </friction>
        </surface>
      </collision>
      <visual name='left_wheel_visual'>
        <pose>0 0 0 0 -0 0</pose>
        <geometry>
          <cylinder>
            <length>0.0682625</length>
            <radius>0.085725</radius>
          </cylinder>
        </geometry>
        <material>
          <script>
            <name>Gazebo/Red</name>
            <uri>file://media/materials/scripts/gazebo.material</uri>
          </script>
        </material>
      </visual>
      <gravity>1</gravity>
    </link>
    <joint name='base_to_right_wheel' type='revolute'>
      <pose relative_to='base_link'>0 -0.27305 0.085725 1.5707 -0 0</pose>
      <parent>base_link</parent>
      <child>right_wheel</child>
      <axis>
        <xyz>0 0 1</xyz>
        <limit>
          <lower>-1e+16</lower>
          <upper>1e+16</upper>
        </limit>
        <dynamics>
          <spring_reference>0</spring_reference>
          <spring_stiffness>0</spring_stiffness>
        </dynamics>
      </axis>
    </joint>
    <link name='right_wheel'>
      <pose relative_to='base_to_right_wheel'>0 0 0 0 -0 0</pose>
      <inertial>
        <pose>0 0 0 0 -0 0</pose>
        <mass>1</mass>
        <inertia>
          <ixx>0.00222551</ixx>
          <ixy>0</ixy>
          <ixz>0</ixz>
          <iyy>0.00222551</iyy>
          <iyz>0</iyz>
          <izz>0.00367439</izz>
        </inertia>
      </inertial>
      <collision name='right_wheel_collision'>
        <pose>0 0 0 0 -0 0</pose>
        <geometry>
          <cylinder>
            <length>0.0682625</length>
            <radius>0.085725</radius>
          </cylinder>
        </geometry>
        <surface>
          <contact>
            <ode/>
          </contact>
          <friction>
            <ode/>
          </friction>
        </surface>
      </collision>
      <visual name='right_wheel_visual'>
        <pose>0 0 0 0 -0 0</pose>
        <geometry>
          <cylinder>
            <length>0.0682625</length>
            <radius>0.085725</radius>
          </cylinder>
        </geometry>
        <material>
          <script>
            <name>Gazebo/Green</name>
            <uri>file://media/materials/scripts/gazebo.material</uri>
          </script>
        </material>
      </visual>
      <gravity>1</gravity>
    </link>
    <static>0</static>
    <plugin name='differential_drive_controller' filename='libgazebo_ros_diff_drive.so'>
      <rosDebugLevel>Debug</rosDebugLevel>
      <publishWheelTF>0</publishWheelTF>
      <robotNamespace>/</robotNamespace>
      <publishTf>1</publishTf>
      <publishWheelJointState>0</publishWheelJointState>
      <alwaysOn>1</alwaysOn>
      <updateRate>100.0</updateRate>
      <leftJoint>base_to_left_wheel</leftJoint>
      <rightJoint>base_to_right_wheel</rightJoint>
      <wheelSeparation>0.5461</wheelSeparation>
      <wheelDiameter>0.17145</wheelDiameter>
      <broadcastTF>1</broadcastTF>
      <wheelTorque>30</wheelTorque>
      <wheelAcceleration>1.8</wheelAcceleration>
      <commandTopic>cmd_vel</commandTopic>
      <odometryFrame>odom</odometryFrame>
      <odometryTopic>odom</odometryTopic>
      <robotBaseFrame>base_link</robotBaseFrame>
    </plugin>
  </model>
</sdf>
